Workbook

Sheet Capa
B2: SISTEMA DE PRECIFICAÇÃO TRIBUTÁRIA
B4: Regime Atual x Reforma Tributária (CBS / IBS / IS) — Transição 2026–2033
B6: Elaborado para: | C6: [Nome do Cliente]
B7: Elaborado por: | C7: [Contador(a) / Consultor(a) Responsável]
B8: Data de referência: | C8: 29/07/2026
B10: COMO USAR ESTA PLANILHA
B11: 1. Aba 'Parâmetros': revise as alíquotas do regime atual e as estimativas de CBS/IBS/IS e o cronograma de transição. Ajuste sempre que houver nova regulamentação (Lei Complementar / Resolução do Senado).
B12: 2. Aba 'Dados de Entrada': preencha os dados do produto/serviço, regime tributário do cliente, custos, despesas e margem desejada.
B13: 3. Aba 'Cálculo Regime Atual': mostra a carga tributária e o preço de venda ANTES da Reforma (Simples Nacional, Lucro Presumido e Lucro Real).
B14: 4. Aba 'Cálculo Reforma 2027-2033': mostra, ano a ano, a carga tributária efetiva (CBS+IBS+IS) durante a transição e o preço de venda necessário.
B15: 5. Aba 'Comparativo Consolidado': resume a evolução da carga tributária e do preço de venda de 2026 a 2033, com gráfico.
B16: 6. Aba 'Simples - Único x Híbrido': exclusiva para clientes do Simples Nacional — compara o Regime Único (IBS/CBS por dentro do DAS) com o Regime Híbrido (por fora, crédito pleno ao comprador B2B), conforme LC 214/2025, art. 41 §3º.
B17: 7. Aba 'Memória de Cálculo': documenta fórmulas, premissas, fontes legais e observações técnicas.
B19: LEGENDA DE CORES
B20: Exemplo | C20: Célula de entrada — edite aqui
B21: Exemplo | C21: Fórmula — não editar
B22: Exemplo | C22: Link/referência para outra aba
B23: Exemplo | C23: Premissa-chave / estimativa a confirmar na regulamentação
B24: Exemplo | C24: Resultado / total
B26: AVISO IMPORTANTE
B27: As alíquotas de referência da CBS e do IBS ainda dependem de regulamentação final (Resolução do Senado Federal, nos termos do art. 156-A e art. 195, V, da CF/88, com redação da EC 132/2023, e da LC 214/2025). Os percentuais aqui utilizados são ESTIMATIVAS técnicas (Ministério da Fazenda / IFI, 2024-2025) para fins de simulação e devem ser atualizados pelo contador assim que os valores oficiais forem publicados. Esta planilha é uma ferramenta de apoio gerencial e não substitui a apuração fiscal formal.

Sheet Parâmetros
B2: PARÂMETROS TRIBUTÁRIOS
B4: 1. TRIBUTOS DO REGIME ATUAL (ANTES DA REFORMA)
B5: Tributo / Parâmetro | C5: Alíquota | D5: Observação
B6: PIS – Regime Cumulativo (Lucro Presumido) | C6: 0.0065 | D6: Lei 9.715/1998. Base: receita bruta, sem direito a crédito.
B7: PIS – Regime Não Cumulativo (Lucro Real) | C7: 0.0165 | D7: Lei 10.637/2002. Permite crédito sobre insumos.
B8: COFINS – Regime Cumulativo (Lucro Presumido) | C8: 0.03 | D8: Lei 9.718/1998. Base: receita bruta, sem direito a crédito.
B9: COFINS – Regime Não Cumulativo (Lucro Real) | C9: 0.076 | D9: Lei 10.833/2003. Permite crédito sobre insumos.
B10: ICMS – Alíquota Interna (UF do cliente) | C10: 0.18 | D10: Editar conforme UF (varia de 17% a 22%). Ex.: SP 18%, RJ 20%.
B11: ISS – Alíquota Municipal | C11: 0.03 | D11: Editar conforme município (mínimo 2% – LC 116/2003, máx. 5%).
B12: IPI – Alíquota Média (se aplicável) | C12: 0.1 | D12: Varia por NCM/TIPI. Ajustar conforme o produto; 0% se não industrializado.
B13: Simples Nacional – Alíquota Efetiva (DAS) | C13: 0.06 | D13: Alíquota efetiva do Anexo/Faixa do cliente (RBT12). Calcular à parte na apuração do Simples.
B15: 2. REFORMA TRIBUTÁRIA — CBS / IBS / IS (ESTIMATIVAS DE REFERÊNCIA)
B16: Tributo / Parâmetro | C16: Alíquota | D16: Observação
B17: CBS – Contribuição sobre Bens e Serviços (Federal) | C17: 0.088 | D17: Estimativa técnica (Min. Fazenda / IFI, 2024-25). Substitui PIS e COFINS. Confirmar via Resolução do Senado.
B18: IBS – Parcela Estadual | C18: 0.142 | D18: Estimativa técnica. Substitui o ICMS. Alíquota de referência fixada por Resolução do Senado (art. 156-A, §1º, XI, CF).
B19: IBS – Parcela Municipal | C19: 0.035 | D19: Estimativa técnica. Substitui o ISS.
B20: IBS Total (Estadual + Municipal) | C20: =C18+C19 | D20: Soma automática.
B21: IVA Dual Total (CBS + IBS) | C21: =C17+C20 | D21: Referência: carga nominal cheia (sem créditos) quando a transição estiver 100% concluída (2033).
B22: IS – Imposto Seletivo (produto específico) | C22: 0 | D22: Incide sobre produtos prejudiciais à saúde/meio ambiente (cigarros, bebidas alcoólicas, veículos poluentes, etc.). 0% se não aplicável.
B23: Crédito Presumido – Resíduos Sólidos, CBS (Art. 170, LC 214/2025) | C23: 0.07 | D23: Percentual fixo previsto em lei (7%) sobre aquisições de resíduos sólidos de coletores incentivados (catador pessoa física, cooperativa ou associação), para destinação final ambientalmente adequada. Vigora junto com a CBS (a partir de 2027). Exclusões no §3º do art. 170 (ex.: agrotóxicos, medicamentos, pilhas/baterias).
B24: Crédito Presumido – Resíduos Sólidos, IBS pleno (Art. 170, LC 214/2025) | C24: 0.13 | D24: Percentual pleno (13%, a partir de 2033) sobre a mesma base. Escalonado de 1,3% (2029) a 13% (2033) na mesma proporção do cronograma de transição do IBS (aba usa o peso 'Novo Estadual/Municipal' da linha 3 abaixo para graduar automaticamente).
B26: 3. CRONOGRAMA DE TRANSIÇÃO (EC 132/2023 e LC 214/2025)
B27: Ano | C27: % Antigo (PIS/COFINS) | D27: % Novo (CBS) | E27: % Antigo (ICMS/ISS) | F27: % Novo (IBS) | G27: Observações
B28: 2026 | C28: 1 | D28: 0 | E28: 1 | F28: 0 | G28: Ano-teste: CBS 0,9% e IBS 0,1% são compensáveis com PIS/COFINS/ICMS/ISS devidos (sem custo adicional líquido).
B29: 2027 | C29: 0 | D29: 1 | E29: 1 | F29: 0 | G29: Extinção de PIS e COFINS; CBS em alíquota cheia. IPI reduzido a 0% (exceto Zona Franca de Manaus). IBS ainda em fase de teste (0,1%).
B30: 2028 | C30: 0 | D30: 1 | E30: 1 | F30: 0 | G30: Mantém-se a sistemática de 2027 (CBS plena / ICMS-ISS integrais).
B31: 2029 | C31: 0 | D31: 1 | E31: 0.9 | F31: 0.1 | G31: Início da transição do IBS: redução de 10% em ICMS e ISS.
B32: 2030 | C32: 0 | D32: 1 | E32: 0.8 | F32: 0.2 | G32: Redução de 20% em ICMS e ISS.
B33: 2031 | C33: 0 | D33: 1 | E33: 0.7 | F33: 0.3 | G33: Redução de 30% em ICMS e ISS.
B34: 2032 | C34: 0 | D34: 1 | E34: 0.6 | F34: 0.4 | G34: Redução de 40% em ICMS e ISS.
B35: 2033 | C35: 0 | D35: 1 | E35: 0 | F35: 1 | G35: Extinção total do ICMS e do ISS. IBS e CBS plenamente vigentes.
B37: Observação: os pesos acima refletem o desenho geral da transição previsto na EC 132/2023 e na LC 214/2025. Ajustes supervenientes por lei complementar/resolução devem ser refletidos diretamente nesta tabela.

Sheet Dados de Entrada
B2: DADOS DE ENTRADA
B4: 1. IDENTIFICAÇÃO
B5: Produto / Serviço | C5: [Descrição do produto ou serviço]
B6: Tipo de Operação | C6: Mercadoria | D6: Mercadoria ou Serviço
B7: Regime Tributário do Cliente | C7: Lucro Presumido | D7: Simples Nacional / Lucro Presumido / Lucro Real
B8: UF | C8: SP | D8: Unidade da Federação
B9: Município | C9: [Município]
B10: Produto sujeito a IPI? (Sim/Não) | C10: Não
B11: Produto sujeito a Imposto Seletivo? (Sim/Não) | C11: Não
B12: Adquire resíduos sólidos de catadores incentivados p/ destinação final adequada? (Sim/Não) | C12: Não | D12: Crédito presumido do Art. 170, LC 214/2025 (setor de reciclagem/sucata)
B14: 2. CUSTOS, DESPESAS E MARGEM
B15: Custo de Aquisição/Produção Unitário (R$) | C15: 100
B16: Valor das Aquisições de Resíduos Sólidos de Catadores Incentivados (R$) | C16: 0 | D16: Preencher somente se o campo acima for 'Sim'. Base de cálculo do crédito presumido do Art. 170, LC 214/2025.
B17: Insumos Sujeitos a Crédito Tributário (R$) | C17: 70 | D17: Parcela do custo acima referente a insumos com direito a crédito (compras de PJ, com nota fiscal).
B18: % de Aproveitamento do Crédito | C18: 1 | D18: 100% para Lucro Real e Reforma (não cumulativo pleno); 0% para Simples/Presumido no regime atual.
B19: Despesas Variáveis (%) — comissões, frete, cartão etc. | C19: 0.05
B20: Despesas Fixas Rateadas (%) | C20: 0.1
B21: Margem de Lucro Desejada (%) | C21: 0.2
B23: 3. RESUMO
B24: Custo Total (base para formação de preço) | C24: =C15
B25: Soma Despesas Variáveis + Despesas Fixas + Margem | C25: =C19+C20+C21

Sheet Cálculo Regime Atual
B2: CÁLCULO — REGIME ATUAL (ANTES DA REFORMA)
B4: Regime Tributário Selecionado: | C4: ='Dados de Entrada'!C7
B5: Tipo de Operação: | C5: ='Dados de Entrada'!C6
B7: A. SIMPLES NACIONAL
B8: Alíquota Efetiva do DAS | C8: =Parâmetros!C13
B9: Carga Tributária (sem créditos) | C9: =C8 | D9: Regra geral: o Simples Nacional não gera créditos ao adquirente na sistemática atual.
B11: B. LUCRO PRESUMIDO
B12: PIS (cumulativo) | C12: =Parâmetros!C6
B13: COFINS (cumulativo) | C13: =Parâmetros!C8
B14: ICMS ou ISS (conforme tipo de operação) | C14: =IF('Dados de Entrada'!C6="Mercadoria",Parâmetros!C10,Parâmetros!C11)
B15: IPI (se aplicável) | C15: =IF('Dados de Entrada'!C10="Sim",Parâmetros!C12,0)
B16: Carga Tributária Total (sem créditos) | C16: =SUM(C12:C15) | D16: PIS/COFINS cumulativos não geram crédito; ICMS pode gerar crédito físico (não considerado aqui por simplificação).
B18: C. LUCRO REAL
B19: PIS (não cumulativo) | C19: =Parâmetros!C7
B20: COFINS (não cumulativo) | C20: =Parâmetros!C9
B21: ICMS ou ISS (conforme tipo de operação) | C21: =IF('Dados de Entrada'!C6="Mercadoria",Parâmetros!C10,Parâmetros!C11)
B22: IPI (se aplicável) | C22: =IF('Dados de Entrada'!C10="Sim",Parâmetros!C12,0)
B23: Carga Tributária Nominal (débito, sem dedução de créditos) | C23: =SUM(C19:C22)
B24: Créditos Recuperáveis sobre Insumos (R$) | C24: ='Dados de Entrada'!C17*'Dados de Entrada'!C18*C23 | D24: =Insumos com direito a crédito × % aproveitamento × alíquota nominal (PIS+COFINS+ICMS/ISS+IPI). Reduz o custo na formação do preço (não a alíquota).
B26: D. REGIME SELECIONADO — RESUMO
B27: Carga Tributária Efetiva do Regime Selecionado | C27: =IF(C5="Simples Nacional",C9,IF(C5="Lucro Presumido",C16,C23))
B28: Créditos Recuperáveis do Regime Selecionado (R$) | C28: =IF(C5="Lucro Real",C24,0)
B29: Detalhamento — Carga Federal (PIS/COFINS/IPI → futura CBS) | C29: =IF(C5="Simples Nacional",0,IF(C5="Lucro Presumido",C12+C13+C15,C19+C20+C22))
B30: Detalhamento — Carga Estadual/Municipal (ICMS/ISS → futuro IBS) | C30: =IF(C5="Simples Nacional",0,IF(C5="Lucro Presumido",C14,C21)) | D30: Usado na aba 'Cálculo Reforma 2027-2033' para aplicar os pesos de transição de cada esfera (federal x estadual/municipal) separadamente. Para o Simples Nacional, o DAS é preservado como guia unificada (ver Memória de Cálculo).
B32: E. FORMAÇÃO DE PREÇO DE VENDA (MÉTODO DO DIVISOR — "POR DENTRO")
B33: Custo Líquido de Créditos (R$) | C33: ='Dados de Entrada'!C15-C28
B34: Divisor = 1 − (Desp. Var. + Desp. Fixas + Margem + Carga Tributária) | C34: =1-('Dados de Entrada'!C19+'Dados de Entrada'!C20+'Dados de Entrada'!C21+C27)
B35: PREÇO DE VENDA NECESSÁRIO (R$) | C35: =C33/C34
B36: Valor dos Tributos embutidos no Preço (R$) | C36: =C35*C27
B37: Lucro Líquido Projetado (R$) | C37: =C35*'Dados de Entrada'!C21

Sheet Cálculo Reforma 2027-2033
B2: CÁLCULO — TRANSIÇÃO DA REFORMA TRIBUTÁRIA (2026–2033)
B4: Regime Tributário Selecionado: | C4: ='Dados de Entrada'!C7
B6: Ano | C6: =Parâmetros!B28 | D6: =Parâmetros!B29 | E6: =Parâmetros!B30 | F6: =Parâmetros!B31 | G6: =Parâmetros!B32 | H6: =Parâmetros!B33 | I6: =Parâmetros!B34 | J6: =Parâmetros!B35
B7: PESOS DE TRANSIÇÃO (Parâmetros)
B8: % Peso Antigo — Federal (PIS/COFINS/IPI) | C8: =Parâmetros!C28 | D8: =Parâmetros!C29 | E8: =Parâmetros!C30 | F8: =Parâmetros!C31 | G8: =Parâmetros!C32 | H8: =Parâmetros!C33 | I8: =Parâmetros!C34 | J8: =Parâmetros!C35
B9: % Peso Novo — Federal (CBS) | C9: =Parâmetros!D28 | D9: =Parâmetros!D29 | E9: =Parâmetros!D30 | F9: =Parâmetros!D31 | G9: =Parâmetros!D32 | H9: =Parâmetros!D33 | I9: =Parâmetros!D34 | J9: =Parâmetros!D35
B10: % Peso Antigo — Estadual/Municipal (ICMS/ISS) | C10: =Parâmetros!E28 | D10: =Parâmetros!E29 | E10: =Parâmetros!E30 | F10: =Parâmetros!E31 | G10: =Parâmetros!E32 | H10: =Parâmetros!E33 | I10: =Parâmetros!E34 | J10: =Parâmetros!E35
B11: % Peso Novo — Estadual/Municipal (IBS) | C11: =Parâmetros!F28 | D11: =Parâmetros!F29 | E11: =Parâmetros!F30 | F11: =Parâmetros!F31 | G11: =Parâmetros!F32 | H11: =Parâmetros!F33 | I11: =Parâmetros!F34 | J11: =Parâmetros!F35
B13: CARGA TRIBUTÁRIA EFETIVA POR ANO
B14: Carga Federal Efetiva (peso antigo × PIS/COFINS/IPI + peso novo × CBS) | C14: =C8*'Cálculo Regime Atual'!$C$29+C9*Parâmetros!$C$17 | D14: =D8*'Cálculo Regime Atual'!$C$29+D9*Parâmetros!$C$17 | E14: =E8*'Cálculo Regime Atual'!$C$29+E9*Parâmetros!$C$17 | F14: =F8*'Cálculo Regime Atual'!$C$29+F9*Parâmetros!$C$17 | G14: =G8*'Cálculo Regime Atual'!$C$29+G9*Parâmetros!$C$17 | H14: =H8*'Cálculo Regime Atual'!$C$29+H9*Parâmetros!$C$17 | I14: =I8*'Cálculo Regime Atual'!$C$29+I9*Parâmetros!$C$17 | J14: =J8*'Cálculo Regime Atual'!$C$29+J9*Parâmetros!$C$17
B15: Carga Estadual/Municipal Efetiva (peso antigo × ICMS/ISS + peso novo × IBS) | C15: =C10*'Cálculo Regime Atual'!$C$30+C11*Parâmetros!$C$20 | D15: =D10*'Cálculo Regime Atual'!$C$30+D11*Parâmetros!$C$20 | E15: =E10*'Cálculo Regime Atual'!$C$30+E11*Parâmetros!$C$20 | F15: =F10*'Cálculo Regime Atual'!$C$30+F11*Parâmetros!$C$20 | G15: =G10*'Cálculo Regime Atual'!$C$30+G11*Parâmetros!$C$20 | H15: =H10*'Cálculo Regime Atual'!$C$30+H11*Parâmetros!$C$20 | I15: =I10*'Cálculo Regime Atual'!$C$30+I11*Parâmetros!$C$20 | J15: =J10*'Cálculo Regime Atual'!$C$30+J11*Parâmetros!$C$20
B16: Imposto Seletivo — IS (se produto sujeito, a partir de 2027) | C16: =IF('Dados de Entrada'!$C$11="Sim",C9*Parâmetros!$C$22,0) | D16: =IF('Dados de Entrada'!$C$11="Sim",D9*Parâmetros!$C$22,0) | E16: =IF('Dados de Entrada'!$C$11="Sim",E9*Parâmetros!$C$22,0) | F16: =IF('Dados de Entrada'!$C$11="Sim",F9*Parâmetros!$C$22,0) | G16: =IF('Dados de Entrada'!$C$11="Sim",G9*Parâmetros!$C$22,0) | H16: =IF('Dados de Entrada'!$C$11="Sim",H9*Parâmetros!$C$22,0) | I16: =IF('Dados de Entrada'!$C$11="Sim",I9*Parâmetros!$C$22,0) | J16: =IF('Dados de Entrada'!$C$11="Sim",J9*Parâmetros!$C$22,0)
B17: CARGA TRIBUTÁRIA TOTAL EFETIVA (ano) | C17: =IF('Dados de Entrada'!$C$7="Simples Nacional",Parâmetros!$C$13,C14+C15+C16) | D17: =IF('Dados de Entrada'!$C$7="Simples Nacional",Parâmetros!$C$13,D14+D15+D16) | E17: =IF('Dados de Entrada'!$C$7="Simples Nacional",Parâmetros!$C$13,E14+E15+E16) | F17: =IF('Dados de Entrada'!$C$7="Simples Nacional",Parâmetros!$C$13,F14+F15+F16) | G17: =IF('Dados de Entrada'!$C$7="Simples Nacional",Parâmetros!$C$13,G14+G15+G16) | H17: =IF('Dados de Entrada'!$C$7="Simples Nacional",Parâmetros!$C$13,H14+H15+H16) | I17: =IF('Dados de Entrada'!$C$7="Simples Nacional",Parâmetros!$C$13,I14+I15+I16) | J17: =IF('Dados de Entrada'!$C$7="Simples Nacional",Parâmetros!$C$13,J14+J15+J16)
B18: Simples Nacional: mantém-se a guia única do DAS (regime não é extinto pela Reforma); a carga do optante padrão permanece pela alíquota efetiva do Simples em todo o período, salvo opção pelo regime regular de apuração do IBS/CBS para repasse de crédito (ver Memória de Cálculo).
B20: CRÉDITO PRESUMIDO — RESÍDUOS SÓLIDOS (ART. 170, LC 214/2025)
B21: Crédito Presumido CBS (7% fixo, a partir de 2027) | C21: =IF('Dados de Entrada'!$C$12="Sim",'Dados de Entrada'!$C$16*C9*Parâmetros!$C$23,0) | D21: =IF('Dados de Entrada'!$C$12="Sim",'Dados de Entrada'!$C$16*D9*Parâmetros!$C$23,0) | E21: =IF('Dados de Entrada'!$C$12="Sim",'Dados de Entrada'!$C$16*E9*Parâmetros!$C$23,0) | F21: =IF('Dados de Entrada'!$C$12="Sim",'Dados de Entrada'!$C$16*F9*Parâmetros!$C$23,0) | G21: =IF('Dados de Entrada'!$C$12="Sim",'Dados de Entrada'!$C$16*G9*Parâmetros!$C$23,0) | H21: =IF('Dados de Entrada'!$C$12="Sim",'Dados de Entrada'!$C$16*H9*Parâmetros!$C$23,0) | I21: =IF('Dados de Entrada'!$C$12="Sim",'Dados de Entrada'!$C$16*I9*Parâmetros!$C$23,0) | J21: =IF('Dados de Entrada'!$C$12="Sim",'Dados de Entrada'!$C$16*J9*Parâmetros!$C$23,0)
B22: Crédito Presumido IBS (escalonado 1,3%→13%, 2029-2033) | C22: =IF('Dados de Entrada'!$C$12="Sim",'Dados de Entrada'!$C$16*C11*Parâmetros!$C$24,0) | D22: =IF('Dados de Entrada'!$C$12="Sim",'Dados de Entrada'!$C$16*D11*Parâmetros!$C$24,0) | E22: =IF('Dados de Entrada'!$C$12="Sim",'Dados de Entrada'!$C$16*E11*Parâmetros!$C$24,0) | F22: =IF('Dados de Entrada'!$C$12="Sim",'Dados de Entrada'!$C$16*F11*Parâmetros!$C$24,0) | G22: =IF('Dados de Entrada'!$C$12="Sim",'Dados de Entrada'!$C$16*G11*Parâmetros!$C$24,0) | H22: =IF('Dados de Entrada'!$C$12="Sim",'Dados de Entrada'!$C$16*H11*Parâmetros!$C$24,0) | I22: =IF('Dados de Entrada'!$C$12="Sim",'Dados de Entrada'!$C$16*I11*Parâmetros!$C$24,0) | J22: =IF('Dados de Entrada'!$C$12="Sim",'Dados de Entrada'!$C$16*J11*Parâmetros!$C$24,0)
B23: Total Crédito Presumido Art. 170 (R$) | C23: =C21+C22 | D23: =D21+D22 | E23: =E21+E22 | F23: =F21+F22 | G23: =G21+G22 | H23: =H21+H22 | I23: =I21+I22 | J23: =J21+J22
B25: CRÉDITOS E FORMAÇÃO DE PREÇO
B26: Créditos Recuperáveis Totais (Insumos + Art. 170) (R$) | C26: =IF('Dados de Entrada'!$C$7="Simples Nacional",0,'Dados de Entrada'!$C$17*'Dados de Entrada'!$C$18*C17)+C23 | D26: =IF('Dados de Entrada'!$C$7="Simples Nacional",0,'Dados de Entrada'!$C$17*'Dados de Entrada'!$C$18*D17)+D23 | E26: =IF('Dados de Entrada'!$C$7="Simples Nacional",0,'Dados de Entrada'!$C$17*'Dados de Entrada'!$C$18*E17)+E23 | F26: =IF('Dados de Entrada'!$C$7="Simples Nacional",0,'Dados de Entrada'!$C$17*'Dados de Entrada'!$C$18*F17)+F23 | G26: =IF('Dados de Entrada'!$C$7="Simples Nacional",0,'Dados de Entrada'!$C$17*'Dados de Entrada'!$C$18*G17)+G23 | H26: =IF('Dados de Entrada'!$C$7="Simples Nacional",0,'Dados de Entrada'!$C$17*'Dados de Entrada'!$C$18*H17)+H23 | I26: =IF('Dados de Entrada'!$C$7="Simples Nacional",0,'Dados de Entrada'!$C$17*'Dados de Entrada'!$C$18*I17)+I23 | J26: =IF('Dados de Entrada'!$C$7="Simples Nacional",0,'Dados de Entrada'!$C$17*'Dados de Entrada'!$C$18*J17)+J23
B27: Custo Líquido de Créditos (R$) | C27: ='Dados de Entrada'!$C$15-C26 | D27: ='Dados de Entrada'!$C$15-D26 | E27: ='Dados de Entrada'!$C$15-E26 | F27: ='Dados de Entrada'!$C$15-F26 | G27: ='Dados de Entrada'!$C$15-G26 | H27: ='Dados de Entrada'!$C$15-H26 | I27: ='Dados de Entrada'!$C$15-I26 | J27: ='Dados de Entrada'!$C$15-J26
B28: Divisor = 1 − (Desp.Var. + Desp.Fixas + Margem + Carga Total) | C28: =1-('Dados de Entrada'!$C$19+'Dados de Entrada'!$C$20+'Dados de Entrada'!$C$21+C17) | D28: =1-('Dados de Entrada'!$C$19+'Dados de Entrada'!$C$20+'Dados de Entrada'!$C$21+D17) | E28: =1-('Dados de Entrada'!$C$19+'Dados de Entrada'!$C$20+'Dados de Entrada'!$C$21+E17) | F28: =1-('Dados de Entrada'!$C$19+'Dados de Entrada'!$C$20+'Dados de Entrada'!$C$21+F17) | G28: =1-('Dados de Entrada'!$C$19+'Dados de Entrada'!$C$20+'Dados de Entrada'!$C$21+G17) | H28: =1-('Dados de Entrada'!$C$19+'Dados de Entrada'!$C$20+'Dados de Entrada'!$C$21+H17) | I28: =1-('Dados de Entrada'!$C$19+'Dados de Entrada'!$C$20+'Dados de Entrada'!$C$21+I17) | J28: =1-('Dados de Entrada'!$C$19+'Dados de Entrada'!$C$20+'Dados de Entrada'!$C$21+J17)
B29: PREÇO DE VENDA NECESSÁRIO (R$) | C29: =C27/C28 | D29: =D27/D28 | E29: =E27/E28 | F29: =F27/F28 | G29: =G27/G28 | H29: =H27/H28 | I29: =I27/I28 | J29: =J27/J28
B30: Variação de Preço vs. Regime Atual (R$) | C30: =C29-'Cálculo Regime Atual'!$C$35 | D30: =D29-'Cálculo Regime Atual'!$C$35 | E30: =E29-'Cálculo Regime Atual'!$C$35 | F30: =F29-'Cálculo Regime Atual'!$C$35 | G30: =G29-'Cálculo Regime Atual'!$C$35 | H30: =H29-'Cálculo Regime Atual'!$C$35 | I30: =I29-'Cálculo Regime Atual'!$C$35 | J30: =J29-'Cálculo Regime Atual'!$C$35
B31: Variação de Preço vs. Regime Atual (%) | C31: =C29/'Cálculo Regime Atual'!$C$35-1 | D31: =D29/'Cálculo Regime Atual'!$C$35-1 | E31: =E29/'Cálculo Regime Atual'!$C$35-1 | F31: =F29/'Cálculo Regime Atual'!$C$35-1 | G31: =G29/'Cálculo Regime Atual'!$C$35-1 | H31: =H29/'Cálculo Regime Atual'!$C$35-1 | I31: =I29/'Cálculo Regime Atual'!$C$35-1 | J31: =J29/'Cálculo Regime Atual'!$C$35-1

Sheet Comparativo Consolidado
B2: COMPARATIVO CONSOLIDADO — 2026 A 2033
B4: Produto/Serviço: | C4: ='Dados de Entrada'!C5
B5: Regime Tributário: | C5: ='Dados de Entrada'!C7
B7: Ano | C7: Carga Tributária Efetiva | D7: Preço de Venda Necessário (R$) | E7: Variação vs. 2026 (R$) | F7: Variação vs. 2026 (%)
B8: ='Cálculo Reforma 2027-2033'!C6 | C8: ='Cálculo Reforma 2027-2033'!C17 | D8: ='Cálculo Reforma 2027-2033'!C29 | E8: ='Cálculo Reforma 2027-2033'!C29-'Cálculo Reforma 2027-2033'!$C$29 | F8: ='Cálculo Reforma 2027-2033'!C29/'Cálculo Reforma 2027-2033'!$C$29-1
B9: ='Cálculo Reforma 2027-2033'!D6 | C9: ='Cálculo Reforma 2027-2033'!D17 | D9: ='Cálculo Reforma 2027-2033'!D29 | E9: ='Cálculo Reforma 2027-2033'!D29-'Cálculo Reforma 2027-2033'!$C$29 | F9: ='Cálculo Reforma 2027-2033'!D29/'Cálculo Reforma 2027-2033'!$C$29-1
B10: ='Cálculo Reforma 2027-2033'!E6 | C10: ='Cálculo Reforma 2027-2033'!E17 | D10: ='Cálculo Reforma 2027-2033'!E29 | E10: ='Cálculo Reforma 2027-2033'!E29-'Cálculo Reforma 2027-2033'!$C$29 | F10: ='Cálculo Reforma 2027-2033'!E29/'Cálculo Reforma 2027-2033'!$C$29-1
B11: ='Cálculo Reforma 2027-2033'!F6 | C11: ='Cálculo Reforma 2027-2033'!F17 | D11: ='Cálculo Reforma 2027-2033'!F29 | E11: ='Cálculo Reforma 2027-2033'!F29-'Cálculo Reforma 2027-2033'!$C$29 | F11: ='Cálculo Reforma 2027-2033'!F29/'Cálculo Reforma 2027-2033'!$C$29-1
B12: ='Cálculo Reforma 2027-2033'!G6 | C12: ='Cálculo Reforma 2027-2033'!G17 | D12: ='Cálculo Reforma 2027-2033'!G29 | E12: ='Cálculo Reforma 2027-2033'!G29-'Cálculo Reforma 2027-2033'!$C$29 | F12: ='Cálculo Reforma 2027-2033'!G29/'Cálculo Reforma 2027-2033'!$C$29-1
B13: ='Cálculo Reforma 2027-2033'!H6 | C13: ='Cálculo Reforma 2027-2033'!H17 | D13: ='Cálculo Reforma 2027-2033'!H29 | E13: ='Cálculo Reforma 2027-2033'!H29-'Cálculo Reforma 2027-2033'!$C$29 | F13: ='Cálculo Reforma 2027-2033'!H29/'Cálculo Reforma 2027-2033'!$C$29-1
B14: ='Cálculo Reforma 2027-2033'!I6 | C14: ='Cálculo Reforma 2027-2033'!I17 | D14: ='Cálculo Reforma 2027-2033'!I29 | E14: ='Cálculo Reforma 2027-2033'!I29-'Cálculo Reforma 2027-2033'!$C$29 | F14: ='Cálculo Reforma 2027-2033'!I29/'Cálculo Reforma 2027-2033'!$C$29-1
B15: ='Cálculo Reforma 2027-2033'!J6 | C15: ='Cálculo Reforma 2027-2033'!J17 | D15: ='Cálculo Reforma 2027-2033'!J29 | E15: ='Cálculo Reforma 2027-2033'!J29-'Cálculo Reforma 2027-2033'!$C$29 | F15: ='Cálculo Reforma 2027-2033'!J29/'Cálculo Reforma 2027-2033'!$C$29-1
B17: Observação: a coluna 'Variação vs. 2026' usa como base o preço de venda calculado antes da Reforma (2026 = mesma carga tributária do regime atual, pois a transição só começa a produzir efeito líquido a partir de 2027/2029).

Sheet Simples - Único x Híbrido
B2: SIMPLES NACIONAL — REGIME ÚNICO x REGIME HÍBRIDO (LC 214/2025)
B3: Aplicável somente se o Regime Tributário em 'Dados de Entrada' for Simples Nacional. Ferramenta de apoio à decisão — não substitui parecer individualizado.
B5: 1. DADOS DO CLIENTE (SIMPLES NACIONAL)
B6: Anexo do Simples Nacional | C6: I | D6: I=Comércio, II=Indústria, III=Serviços (Fator R), IV=Serviços (CPP à parte), V=Serviços (Fator R<28%)
B7: RBT12 — Receita Bruta Acumulada 12 Meses (R$) | C7: 1200000
B8: Alíquota Nominal da Faixa (%) | C8: 0.19 | D8: Consultar tabela oficial da faixa/Anexo aplicável (LC 123/2006, Anexos I a V, Portal do Simples Nacional).
B9: Parcela a Deduzir da Faixa (R$) | C9: 22500
B10: % do Anexo correspondente a ICMS/ISS/PIS/COFINS | C10: 0.4 | D10: ESTIMATIVA — usar a tabela de repartição percentual do Anexo/faixa aplicável (LC 123/2006). É a parcela da alíquota efetiva que hoje corresponde aos tributos substituídos por IBS/CBS.
B12: 2. REGIME ÚNICO (HOJE) — ALÍQUOTA EFETIVA E CRÉDITO GERADO
B13: Alíquota Efetiva = (RBT12×AlíqNominal − ParcDeduzir) / RBT12 | C13: =(C7*C8-C9)/C7
B14: Carga Tributária Anual — Regime Único (R$) | C14: =C7*C13
B15: Componente IBS/CBS Embutido na Alíquota Efetiva (%) | C15: =C13*C10
B16: Componente IBS/CBS Embutido — valor anual (R$) | C16: =C7*C15 | D16: É o crédito que o cliente PJ comprador já consegue aproveitar HOJE, mesmo no Regime Único.
B18: 3. PERFIL DA CARTEIRA E ALÍQUOTA DE REFERÊNCIA DA REFORMA
B19: % de Vendas para PJ do Lucro Real/Presumido (B2B com crédito) | C19: 0.5 | D19: Vendas para PJ também optante do Simples não geram ganho de crédito no Híbrido — não incluir nesse percentual.
B20: Redução Setorial de Alíquota (0% / 30% / 60% / 100%) | C20: 0 | D20: Preencher se o setor tiver redução prevista na LC 214/2025 (ex.: profissionais de conselho, saúde, educação, cesta básica etc.).
B21: Alíquota de Referência Cheia (IVA Dual — CBS+IBS) | C21: =Parâmetros!C21 | D21: ESTIMATIVA — não definitiva; depende de Resolução do Senado (LC 214/2025, art. 14).
B22: Alíquota de Referência Aplicável (após redução setorial) | C22: =C21*(1-C20)
B24: 4. IMPACTO NO COMPRADOR — GANHO DE COMPETITIVIDADE (HÍBRIDO)
B25: Receita Anual de Vendas B2B (R$) | C25: =C7*C19
B26: Crédito Pleno Gerado no Híbrido (R$/ano) | C26: =C25*C22
B27: Crédito Hoje sobre a mesma Receita B2B — Regime Único (R$/ano) | C27: =C25*C15
B28: GANHO DE CRÉDITO AO COMPRADOR (R$/ano) | C28: =C26-C27
B29: Ganho de Crédito sobre a Receita B2B (%) | C29: =IF(C25=0,0,C28/C25)
B31: 5. IMPACTO NO PRÓPRIO OPTANTE — CARGA TRIBUTÁRIA DIRETA (HÍBRIDO)
B32: Compras/Insumos Sujeitos a Crédito no Híbrido (R$/ano) | C32: 500000
B33: % de Aproveitamento do Crédito sobre as Compras | C33: 1
B34: Créditos Tomados nas Compras (R$/ano) | C34: =C32*C33*C22
B35: Débito Total de IBS/CBS sobre a Receita Total (R$/ano) | C35: =C7*C22
B36: Carga Líquida de IBS/CBS no Híbrido (Débito − Créditos) (R$/ano) | C36: =C35-C34
B37: Alíquota Efetiva do DAS sem o Componente IBS/CBS (%) | C37: =C13-C15
B38: Demais Tributos do DAS no Híbrido — IRPJ/CSLL/CPP/etc. (R$/ano) | C38: =C7*C37
B39: CARGA TRIBUTÁRIA TOTAL — REGIME HÍBRIDO (R$/ano) | C39: =C38+C36
B40: Impacto Líquido para o Optante — Híbrido vs. Único (R$/ano) | C40: =C39-C14
B41: Impacto Líquido para o Optante (%) | C41: =IF(C14=0,0,C40/C14) | D41: Positivo = carga própria aumenta no Híbrido; negativo = carga própria diminui. Custo de compliance adicional (sistemas, EFD própria, split payment) não está quantificado aqui — avaliar qualitativamente.
B43: 6. QUADRO COMPARATIVO — CENÁRIOS DE MIX DE CARTEIRA
B44: Cenário | C44: % B2B | D44: Ganho de Crédito ao Comprador (R$) | E44: Impacto Líquido no Optante (R$) | F44: Leitura
B45: B2C Majoritário | C45: 0.2 | D45: =(C7*C45)*C22-(C7*C45)*C15 | E45: =C40 | F45: =IF(D45>0,"Híbrido melhora crédito do comprador","Sem ganho relevante de crédito")
B46: Carteira Mista | C46: 0.5 | D46: =(C7*C46)*C22-(C7*C46)*C15 | E46: =C40 | F46: =IF(D46>0,"Híbrido melhora crédito do comprador","Sem ganho relevante de crédito")
B47: B2B Majoritário | C47: 0.8 | D47: =(C7*C47)*C22-(C7*C47)*C15 | E47: =C40 | F47: =IF(D47>0,"Híbrido melhora crédito do comprador","Sem ganho relevante de crédito")
...

Sheet Memória de Cálculo
B2: MEMÓRIA DE CÁLCULO, PREMISSAS E FONTES
B4: 1. BASE LEGAL
B5: • Emenda Constitucional nº 132, de 20/12/2023 — institui a Reforma Tributária sobre o consumo (arts. 156-A, 195, V, e ADCT arts. 125 a 137).
B6: • Lei Complementar nº 214, de 16/01/2025 — regulamenta a CBS, o IBS e o Imposto Seletivo, define regras de não cumulatividade, créditos, cronograma de transição, regimes específicos (Simples Nacional, imunes, cashback) e o Comitê Gestor do IBS.
B7: • Legislação atual: Leis nº 9.715/1998, 9.718/1998 (PIS/COFINS cumulativos), 10.637/2002 e 10.833/2003 (PIS/COFINS não cumulativos), Lei Complementar nº 87/1996 (ICMS), Lei Complementar nº 116/2003 (ISS), Lei Complementar nº 123/2006 (Simples Nacional), RIPI/2010 (IPI).
B8: • LC 214/2025, art. 41, §3º — permite ao optante do Simples Nacional escolher, semestralmente, entre recolher IBS/CBS dentro do DAS (Regime Único) ou por fora, pelas regras gerais do regime não cumulativo (Regime Híbrido). Resolução CGSN nº 183/2025 operacionaliza a opção no âmbito do Simples.
B10: 2. METODOLOGIA APLICADA
B11: 1) Identificação da atividade e do tipo de operação (mercadoria/serviço) — aba 'Dados de Entrada'.
B12: 2) Identificação do regime tributário do cliente (Simples Nacional, Lucro Presumido ou Lucro Real).
B13: 3) Identificação da tributação aplicável em cada esfera (federal: PIS/COFINS/IPI; estadual/municipal: ICMS/ISS) — aba 'Parâmetros'.
B14: 4) Cálculo dos tributos nominais e da carga tributária efetiva do regime atual — aba 'Cálculo Regime Atual'.
B15: 5) Cálculo dos créditos recuperáveis sobre insumos (não cumulatividade) — reduzem o CUSTO na formação de preço, não a alíquota de débito.
... B50: • A leitura indicativa da Seção 8 da aba é apenas um sinalizador inicial baseado no % de vendas B2B e no impacto líquido calculado — a decisão final deve considerar também o custo de compliance, o apetite do cliente para complexidade adicional e a janela de opção vigente.
